<?xml version="1.0"?>

<robot xmlns:xacro="http://www.ros.org/wiki/xacro" name="volcaniarm">

  <!-- World link (fixed reference frame) -->
  <link name="world"/>

  <!-- Fixed joint to keep the robot in place -->
  <joint name="world_to_base" type="fixed">
    <origin xyz="0 0 1.0" rpy="0 0 0"/>
    <parent link="world"/>
    <child link="volcaniarm_base_link"/>
  </joint>

  <!-- volcaniarm_base_link -->
  <link name="volcaniarm_base_link">
    <inertial>
      <origin xyz="-0.0270292275136268 0.0131760845218784 -0.0373225307756109" rpy="0 0 0"/>
      <mass value="13.6269163204302"/>
      <inertia ixx="0.0576447761387568" ixy="2.74831669755734E-05" ixz="5.43946096689231E-06"
               iyy="1.21122548907616" iyz="-1.83402806932084E-05" izz="1.26082925995101"/>
    </inertial>
    <visual>
      <origin xyz="0 0 0" rpy="0 0 0"/>
      <geometry>
        <mesh filename="package://volcaniarm_description/meshes/volcaniarm_base_link.STL"/>
      </geometry>
      <material name="">
        <color rgba="0.792156862745098 0.819607843137255 0.933333333333333 1"/>
      </material>
    </visual>
    <collision>
      <origin xyz="0 0 0" rpy="0 0 0"/>
      <geometry>
        <mesh filename="package://volcaniarm_description/meshes/volcaniarm_base_link.STL"/>
      </geometry>
    </collision>
  </link>

  <!-- delta_arm_base_link -->
  <link name="delta_arm_base_link">
    <inertial>
      <origin xyz="-0.00902773080675034 -1.78293986968781E-05 -0.0512376164000921" rpy="0 0 0"/>
      <mass value="2.15013589886699"/>
      <inertia ixx="0.00670575094115183" ixy="-5.65872149932825E-09" ixz="2.35502761390986E-06"
               iyy="0.00584240556923599" iyz="3.00404195469226E-11" izz="0.0113637883201367"/>
    </inertial>
    <visual>
      <origin xyz="0 0 0" rpy="0 0 0"/>
      <geometry>
        <mesh filename="package://volcaniarm_description/meshes/delta_arm_base_link.STL"/>
      </geometry>
      <material name="">
        <color rgba="0.792156862745098 0.819607843137255 0.933333333333333 1"/>
      </material>
    </visual>
    <collision>
      <origin xyz="0 0 0" rpy="0 0 0"/>
      <geometry>
        <mesh filename="package://volcaniarm_description/meshes/delta_arm_base_link.STL"/>
      </geometry>
    </collision>
  </link>

  <joint name="delta_arm_base_joint" type="prismatic">
    <origin xyz="-0.069512 0 -0.0905" rpy="0 0 0"/>
    <parent link="volcaniarm_base_link"/>
    <child link="delta_arm_base_link"/>
    <axis xyz="-1 0 0"/>
    <limit lower="-0.5" upper="0.3" effort="10" velocity="10"/>
  </joint>

  <!-- right_elbow_link -->
  <link name="right_elbow_link">
    <inertial>
      <origin xyz="-1.10526378793718E-05 8.25561841111266E-13 0.169908181946343" rpy="0 0 0"/>
      <mass value="0.57558402444417"/>
      <inertia ixx="0.00641206627372397" ixy="-1.17949337905161E-19" ixz="-1.08070667288964E-06"
               iyy="0.00641457318952708" iyz="-3.11708124589583E-19" izz="0.000156325566535823"/>
    </inertial>
    <visual>
      <origin xyz="0 0 0" rpy="0 0 0"/>
      <geometry>
        <mesh filename="package://volcaniarm_description/meshes/right_elbow_link.STL"/>
      </geometry>
      <material name="">
        <color rgba="0.792156862745098 0.819607843137255 0.933333333333333 1"/>
      </material>
    </visual>
    <collision>
      <origin xyz="0 0 0" rpy="0 0 0"/>
      <geometry>
        <mesh filename="package://volcaniarm_description/meshes/right_elbow_link.STL"/>
      </geometry>
    </collision>
  </link>

  <joint name="right_elbow_joint" type="revolute">
    <origin xyz="0.03 -0.085 -0.1035" rpy="2.4621 0 0"/>
    <parent link="delta_arm_base_link"/>
    <child link="right_elbow_link"/>
    <axis xyz="1 0 0"/>
    <limit lower="-1.57" upper="1.57" effort="10" velocity="10"/>
  </joint>

  <!-- left_elbow_link -->
  <link name="left_elbow_link">
    <inertial>
      <origin xyz="-1.10526381558174E-05 -3.52899931499451E-11 0.169908182007537" rpy="0 0 0"/>
      <mass value="0.575584024444165"/>
      <inertia ixx="0.00641206627372392" ixy="5.31513174401966E-20" ixz="-1.08070667288878E-06"
               iyy="0.00641457318952703" iyz="2.59530895038718E-18" izz="0.000156325566535821"/>
    </inertial>
    <visual>
      <origin xyz="0 0 0" rpy="0 0 0"/>
      <geometry>
        <mesh filename="package://volcaniarm_description/meshes/left_elbow_link.STL"/>
      </geometry>
      <material name="">
        <color rgba="0.792156862745098 0.819607843137255 0.933333333333333 1"/>
      </material>
    </visual>
    <collision>
      <origin xyz="0 0 0" rpy="0 0 0"/>
      <geometry>
        <mesh filename="package://volcaniarm_description/meshes/left_elbow_link.STL"/>
      </geometry>
    </collision>
  </link>

  <joint name="left_elbow_joint" type="revolute">
    <origin xyz="0.03 0.085 -0.1035" rpy="-2.2502 0 0"/>
    <parent link="delta_arm_base_link"/>
    <child link="left_elbow_link"/>
    <axis xyz="1 0 0"/>
    <limit lower="-1.57" upper="1.57" effort="0" velocity="0"/>
  </joint>

  <!-- right_arm_link
  <link name="right_arm_link">
    <inertial>
      <origin xyz="-0.00171452755479162 1.13797860024079E-12 0.23102414279737" rpy="0 0 0"/>
      <mass value="0.348231414720761"/>
      <inertia ixx="0.00919901976462265" ixy="-3.08319992800528E-19" ixz="0.000114499144557394"
               iyy="0.00916320876569512" iyz="-5.99529920066594E-18" izz="5.69124344640193E-05"/>
    </inertial>
    <visual>
      <origin xyz="0 0 0" rpy="0 0 0"/>
      <geometry>
        <mesh filename="package://volcaniarm_description/meshes/right_arm_link.STL"/>
      </geometry>
      <material name="">
        <color rgba="0.792156862745098 0.819607843137255 0.933333333333333 1"/>
      </material>
    </visual>
    <collision>
      <origin xyz="0 0 0" rpy="0 0 0"/>
      <geometry>
        <mesh filename="package://volcaniarm_description/meshes/right_arm_link.STL"/>
      </geometry>
    </collision>
  </link>

  <joint name="right_arm_joint" type="revolute">
    <origin xyz="0 0 0.36" rpy="1.4052 0 0"/>
    <parent link="right_elbow_link"/>
    <child link="right_arm_link"/>
    <axis xyz="-1 0 0"/>
    <limit lower="-1.57" upper="1.57" effort="10" velocity="10"/>
  </joint> -->

  <!-- left_arm_link -->
  <!-- <link name="left_arm_link">
    <inertial>
      <origin xyz="0.0017145275657231 2.87547763377916E-13 0.231024142798437" rpy="0 0 0"/>
      <mass value="0.348231414720761"/>
      <inertia ixx="0.00919901976462264" ixy="1.25360876193649E-19" ixz="-0.000114499144557395"
               iyy="0.0091632087656951" iyz="-2.53432257818487E-18" izz="5.69124344640192E-05"/>
    </inertial>
    <visual>
      <origin xyz="0 0 0" rpy="0 0 0"/>
      <geometry>
        <mesh filename="package://volcaniarm_description/meshes/left_arm_link.STL"/>
      </geometry>
      <material name="">
        <color rgba="0.792156862745098 0.819607843137255 0.933333333333333 1"/>
      </material>
    </visual>
    <collision>
      <origin xyz="0 0 0" rpy="0 0 0"/>
      <geometry>
        <mesh filename="package://volcaniarm_description/meshes/left_arm_link.STL"/>
      </geometry>
    </collision>
  </link>

  <joint name="left_arm_joint" type="revolute">
    <origin xyz="0 0 0.36" rpy="-1.4698 0 0"/>
    <parent link="left_elbow_link"/>
    <child link="left_arm_link"/>
    <axis xyz="1 0 0"/>
    <limit lower="-1.57" upper="1.57" effort="0" velocity="0"/>
  </joint> -->

</robot>
